Workbook

Sheet README
A1: AAPNA ATS - Master Test Cases
A2: Version | B2: v1.0 - 2026-10-13
A3: Purpose | B3: Single catalogue of functional test cases across all ATS modules. Each case is tagged with how it will run in the Playwright suite (or why it stays manual), so the same sheet serves the demo and the formal acceptance pass.
A4: Baseline | B4: Carries forward all 118 cases from 'ATS_TestCases_HRUpload_to_ZekoHR_Updated 2.xlsx' (2026-08-11 pass). Their previous result is kept in 'Previous Run (2026-08-11)'. Corrections are listed on the 'Changes vs Previous' sheet.
A5: Target environment | B5: Local dev: frontend (Vite :5173) + backend (:5000) + dedicated test database (to be agreed). External services are NOT called.
A7: Automation legend
A8: Automated - UI | B8: Playwright drives the browser; needs only a running app and seeded users.
A9: Automated - UI (fixture) | B9: Playwright UI test that needs a fixture first - e.g. a journey created via API, or a token (scorecard / documents / MRF approval) read from the test DB.
A10: Automated - API | B10: Playwright API request test (security / authorisation checks with no UI).
A11: Manual - External | B11: Depends on an external service (AI parser/search, Zeko, MS Graph mail/Teams/OneDrive, Turnstile). Skipped in the local suite; run manually on staging.
A12: Manual - Scheduled job | B12: Depends on a cron/background job; run manually by invoking the job.
A13: Manual - Exploratory | B13: Open product question - needs a decision before it can have a pass/fail.
A15: Email checks | B15: Locally, outcome/notification emails cannot be delivered. Automated cases assert the state change and the 'Emails in this round' log; real inbox delivery is a manual staging check (column 'External Dependency' = MS Graph mail).
A16: Priority | B16: P1 = core flow / security, must pass for the demo. P2 = important validation. P3 = secondary.
A17: Status values | B17: Not Run, Pass, Fail, Blocked, Skipped

Sheet Test Cases
A1: TC ID | B1: Module | C1: Feature | D1: Test Scenario | E1: Preconditions / Test Data | F1: Test Steps | G1: Expected Result | H1: Type | I1: Priority | J1: Role | K1: Automation | L1: External Dependency | M1: Source | N1: Previous Run (2026-08-11) | O1: Status | P1: Actual Result | Q1: Remarks
A2: HRU-01 | B2: HR Manual Upload | C2: HR Manual Upload | D2: Upload a single valid resume (PDF) | F2: 1. Go to HR Upload page 2. Upload one .pdf resume with valid name, email, phone 3. Observe Upload Status table | G2: Job status moves Uploaded -> Processing -> Saved to Database; new row created in candidate DB with correctly parsed fields | H2: Positive | I2: P1 | J2: Recruiter | K2: Manual - External | L2: AI resume parser (Gemini / OpenRouter / Cohere) | M2: ATS_TestCases_HRUpload_to_ZekoHR_Updated 2.xlsx | N2: It Ran fine | O2: Not Run | Q2: We are having a issues in Total Experinec as this is not updating when we checked in the search candidate page. Total Experience defect fixed in CHANGES-2026-08-07 #19. Re-test with a CV using 'Jun-2022 - Present', then Search Candidate > View Details.
A3: HRU-02 | B3: HR Manual Upload | C3: HR Manual Upload | D3: Upload exceeding max file count/size | F3: 1. Attempt to upload more than 2 or more files in one request | G3: Job status moves Uploaded -> Processing -> Saved to Database; new row created in candidate DB with correctly parsed fields | H3: Positive | I3: P1 | J3: Recruiter | K3: Manual - External | L3: AI resume parser (Gemini / OpenRouter / Cohere) | M3: ATS_TestCases_HRUpload_to_ZekoHR_Updated 2.xlsx | N3: It Ran fine | O3: Not Run | Q3: Same Issues Scenario title says 'exceeding max count/size' but steps/expected describe a multi-file success. Re-word before next run. Total Experience fix: #19.
A4: HRU-03 | B4: HR Manual Upload | C4: HR Manual Upload | D4: Duplicate resume detected | F4: 1. Re-upload the exact same resume (same email/phone) 2. Observe Upload Status table | G4: Job status becomes 'Pending Recruiter Review' (Duplicate_Pending_Review); action_required = true; recruiter notified (email + socket) | H4: Positive | I4: P1 | J4: Recruiter | K4: Manual - External | L4: AI resume parser (Gemini / OpenRouter / Cohere) | M4: ATS_TestCases_HRUpload_to_ZekoHR_Updated 2.xlsx | N4: It Ran fine | O4: Not Run
A5: HRU-04 | B5: HR Manual Upload | C5: HR Manual Upload | D5: Resolve duplicate via Merge | F5: 1. Click Review on the duplicate row 2. Click Merge | G5: Existing candidate record updated with new data; last_action_context = 'duplicate_merge'; modifiedAt refreshed; job removed from pending review | H5: Positive | I5: P1 | J5: Recruiter | K5: Manual - External | L5: AI resume parser (Gemini / OpenRouter / Cohere) | M5: ATS_TestCases_HRUpload_to_ZekoHR_Updated 2.xlsx | N5: It Ran fine | O5: Not Run
A6: HRU-05 | B6: HR Manual Upload | C6: HR Manual Upload | D6: Resolve duplicate via Cancel | F6: 1. Click Review on the duplicate row 2. Click Cancel | G6: Job status becomes 'Rejected by Recruiter' (Cancelled); original candidate record left untouched; no merge happens | H6: Positive | I6: P1 | J6: Recruiter | K6: Manual - External | L6: AI resume parser (Gemini / OpenRouter / Cohere) | M6: ATS_TestCases_HRUpload_to_ZekoHR_Updated 2.xlsx | N6: It Ran fine | O6: Not Run
A7: HRU-06 | B7: HR Manual Upload | C7: HR Manual Upload | D7: Resume with no email AND no phone | F7: 1. Upload a resume that has no email address and no phone number anywhere in the text | G7: Job status = 'Rejected by System' (Rejected_By_System); candidate NOT saved to DB; not reprocessable | H7: Negative | I7: P1 | J7: Recruiter | K7: Manual - External | L7: AI resume parser (Gemini / OpenRouter / Cohere) | M7: ATS_TestCases_HRUpload_to_ZekoHR_Updated 2.xlsx | N7: Not executed | O7: Not Run | Q7: Never executed (no Actual Result in the 2026-08-11 pass).
A8: HRU-07 | B8: HR Manual Upload | C8: HR Manual Upload | D8: Resume with email but no phone | F8: 1. Upload a resume with a valid email but no phone number | G8: Candidate is saved; 'missing data' collection email/token sent to candidate for the missing field | H8: Positive | I8: P1 | J8: Recruiter | K8: Manual - External | L8: AI resume parser (Gemini / OpenRouter / Cohere) | M8: ATS_TestCases_HRUpload_to_ZekoHR_Updated 2.xlsx | N8: Not executed | O8: Not Run | Q8: Never executed. Missing-data link also exercised by MJD-01..04.
A9: HRU-08 | B9: HR Manual Upload | C9: HR Manual Upload | D9: Resume with phone but no email | F9: 1. Upload a resume with a valid phone but no email address | G9: Candidate is saved; 'missing data' collection email/token flow triggered (via alternate contact if available) | H9: Positive | I9: P1 | J9: Recruiter | K9: Manual - External | L9: AI resume parser (Gemini / OpenRouter / Cohere) | M9: ATS_TestCases_HRUpload_to_ZekoHR_Updated 2.xlsx | N9: Not executed | O9: Not Run | Q9: Never executed.
A10: HRU-09 | B10: HR Manual Upload | C10: HR Manual Upload | D10: Live dashboard updates without manual refresh | F10: 1. Keep Upload Status table open in Tab A 2. Upload a new resume from Tab B 3. Observe Tab A | G10: Tab A's Upload Status table updates live (socket event) without a manual page refresh | H10: Positive | I10: P1 | J10: Recruiter | K10: Manual - External | L10: AI resume parser (Gemini / OpenRouter / Cohere) | M10: ATS_TestCases_HRUpload_to_ZekoHR_Updated 2.xlsx | N10: Not executed | O10: Not Run | Q10: Never executed. Live socket update itself is automatable once a job can be produced without the AI parser.
A11: SCR-01 | B11: Candidate Screening | C11: Candidate Screening - Shortlist | D11: Shortlist a new candidate for an MRF role | F11: 1. Go to Candidate Screening, select the MRF role 2. Select the candidate 3. Click Shortlist (send_email = true) | G11: rpa_shortlisted_candidates row created with pipeline_status = 'shortlisted'; candidate's FinalStatus = 'Stage 0 - Resume Shortlisted'; a pipeline journey is auto-created and candidate appears on Pipeline Tracker at the 'HR Screening (Zeko)' stage; shortlist email sent to candidate (staging inbox) | H11: Positive | I11: P1 | J11: Recruiter | K11: Manual - External | L11: AI embeddings (Gemini) for JD / keyword search | M11: ATS_TestCases_HRUpload_to_ZekoHR_Updated 2.xlsx | N11: It Ran fine | O11: Not Run
A12: SCR-02 | B12: Candidate Screening | C12: Candidate Screening - Shortlist | D12: Re-shortlist an already-shortlisted candidate (same MRF) | F12: 1. Attempt to shortlist the same candidate for the same MRF again | G12: Action is skipped (no duplicate record, no duplicate email); existing shortlist record is left as-is | H12: Positive | I12: P1 | J12: Recruiter | K12: Manual - External | L12: AI embeddings (Gemini) for JD / keyword search | M12: ATS_TestCases_HRUpload_to_ZekoHR_Updated 2.xlsx | N12: It Ran fine | O12: Not Run
A13: SCR-03 | B13: Candidate Screening | C13: Candidate Screening - Shortlist | D13: Shortlist via keyword search (no MRF) | F13: 1. Run a keyword search in Screening 2. Shortlist a resulting candidate without an MRF context | G13: rpa_shortlisted_candidates.mrf_id is stored as NULL (not 0); pipeline journey still created at HR Screening (Zeko) stage | H13: Positive | I13: P1 | J13: Recruiter | K13: Manual - External | L13: AI embeddings (Gemini) for JD / keyword search | M13: ATS_TestCases_HRUpload_to_ZekoHR_Updated 2.xlsx | N13: It Ran fine | O13: Not Run
A14: SCR-04 | B14: Candidate Screening | C14: Candidate Screening - Reject | D14: Reject a candidate with a reason | F14: 1. Select the candidate 2. Click Reject, choose/enter a rejection reason 3. Submit | G14: rpa_shortlisted_candidates row set to pipeline_status = 'rejected' with the reason stored; candidate's FinalStatus = 'Rejected'; rejection email sent to candidate; NO pipeline journey is created (candidate does not appear on Pipeline Tracker) | H14: Positive | I14: P1 | J14: Recruiter | K14: Manual - External | L14: AI embeddings (Gemini) for JD / keyword search | M14: ATS_TestCases_HRUpload_to_ZekoHR_Updated 2.xlsx | N14: It Ran fine | O14: Not Run
A15: SCR-05 | B15: Candidate Screening | C15: Candidate Screening - Reject | D15: Reject a candidate without providing a reason | F15: 1. Click Reject without selecting/entering any reason 2. Submit | G15: Request is blocked with a validation error: 'A rejection reason is required' | H15: Negative | I15: P1 | J15: Recruiter | K15: Manual - External | L15: AI embeddings (Gemini) for JD / keyword search | M15: ATS_TestCases_HRUpload_to_ZekoHR_Updated 2.xlsx | N15: It Ran fine | O15: Not Run | Q15: Validation itself is client-side; only reaching the result list needs AI search.
A16: SCR-06 | B16: Candidate Screening | C16: Candidate Screening - Reject | D16: Reject a previously shortlisted candidate | F16: 1. Reject the same candidate for the same MRF, with a reason | G16: Existing record flips to 'rejected'; the who/when (rejected-by, rejected-at) fields update to reflect this latest action, not the original shortlister | H16: Positive | I16: P1 | J16: Recruiter | K16: Manual - External | L16: AI embeddings (Gemini) for JD / keyword search | M16: ATS_TestCases_HRUpload_to_ZekoHR_Updated 2.xlsx | N16: It Ran fine | O16: Not Run
A17: CPIPE-01 | B17: Candidate Pipeline | C17: Pipeline Entry (Post-Shortlist) | D17: Shortlisted candidate lands directly on 'HR Screening (Zeko)' stage | E17: Journey created by shortlisting via API (fixture) because the screening search needs AI embeddings. | F17: 1. Open Pipeline Tracker 2. Locate the candidate's card | G17: Candidate appears directly under the 'HR Screening (Zeko)' column (there is no separate visible 'Shortlisted' column - that stage is inactive/hidden by design) | H17: Positive | I17: P1 | J17: Recruiter | K17: Automated - UI (fixture) | M17: ATS_TestCases_HRUpload_to_ZekoHR_Updated 2.xlsx | N17: It Ran fine | O17: Not Run
A18: CPIPE-02 | B18: Candidate Pipeline | C18: Pipeline Entry (Post-Shortlist) | D18: Drawer shows read-only shortlist context | E18: Journey created by shortlisting via API (fixture). | F18: 1. Open the candidate's journey drawer | G18: Drawer header shows shortlisted date, shortlisted by, and recruiter notes as read-only context (not an editable stage) | H18: Positive | I18: P1 | J18: Recruiter | K18: Automated - UI (fixture) | M18: ATS_TestCases_HRUpload_to_ZekoHR_Updated 2.xlsx | N18: It Ran fine | O18: Not Run
A19: ZHR-01 | B19: Zeko HR Screening | C19: Zeko HR Screening - Assign & Schedule | D19: Assign candidate to a Zeko job | F19: 1. From Screening's Zeko panel, assign the candidate to a Zeko job | G19: A row is created in the Zeko candidate pipeline table with stage='hr', status='pending' | H19: Positive | I19: P2 | J19: Recruiter | K19: Manual - External | L19: Zeko API | M19: ATS_TestCases_HRUpload_to_ZekoHR_Updated 2.xlsx | N19: It Ran fine | O19: Not Run
A20: ZHR-02 | B20: Zeko HR Screening | C20: Zeko HR Screening - Assign & Schedule | D20: Schedule the Zeko interview with valid slot | F20: 1. Pick a start/end time and schedule the interview | G20: Zeko schedule API is called; pipeline row status moves to 'sent'; start/end times are rounded to the next 30-minute boundary before being sent to Zeko | H20: Positive | I20: P2 | J20: Recruiter | K20: Manual - External | L20: Zeko API | M20: ATS_TestCases_HRUpload_to_ZekoHR_Updated 2.xlsx | N20: It Ran fine | O20: Not Run
A21: ZHR-03 | B21: Zeko HR Screening | C21: Zeko HR Screening - Assign & Schedule | D21: Cancel a scheduled interview with a reason | F21: 1. Cancel the interview, providing a cancellation reason | G21: Zeko cancel API is called (best-effort - a Zeko-side failure does not block the local update); pipeline row status = 'cancelled', cancel reason and cancelled-at timestamp stored; cancellation email sent to the candidate | H21: Positive | I21: P2 | J21: Recruiter | K21: Manual - External | L21: Zeko API | M21: ATS_TestCases_HRUpload_to_ZekoHR_Updated 2.xlsx | N21: It Ran fine | O21: Not Run
A22: ZHR-04 | B22: Zeko HR Screening | C22: Zeko HR Screening - Assign & Schedule | D22: Cancel an interview without a reason | F22: 1. Attempt to cancel without entering a reason | G22: Cancellation succeeds without a reason - the reason field is optional. Pipeline row status = 'cancelled'. | H22: Positive | I22: P2 | J22: Recruiter | K22: Manual - External | L22: Zeko API | M22: ATS_TestCases_HRUpload_to_ZekoHR_Updated 2.xlsx | N22: It Ran fine | O22: Not Run | Q22: Expected result clarified (was 'As it's Optional').
A23: ZHR-05 | B23: Zeko HR Screening | C23: Zeko HR Screening - Results & Scores | D23: Result auto-fetch after interview window ends | F23: 1. Wait for / trigger the Zeko results-fetch job (hourly cron) | G23: A result row is created with overall/technical/communication scores and report link; the Zeko pipeline row status moves to 'completed'; scores are written back to the candidate's profile (matched by candidate email) | H23: Positive | I23: P2 | J23: Recruiter | K23: Manual - Scheduled job | L23: Zeko API | M23: ATS_TestCases_HRUpload_to_ZekoHR_Updated 2.xlsx | N23: It Ran fine | O23: Not Run
A24: ZHR-06 | B24: Zeko HR Screening | C24: Zeko HR Screening - Results & Scores | D24: Result fetch when Zeko has no data yet | F24: 1. Trigger the results-fetch job | G24: Row is skipped this run (remains status='sent'); no error thrown; will be retried on the next scheduled run | H24: Positive | I24: P2 | J24: Recruiter | K24: Manual - Scheduled job | L24: Zeko API | M24: ATS_TestCases_HRUpload_to_ZekoHR_Updated 2.xlsx | N24: Not executed | O24: Not Run | Q24: Never executed.
A25: OUT-01 | B25: Candidate Pipeline | C25: Zeko HR Screening - Outcome (Approve/Reject/Hold) | D25: Approve candidate at HR Screening (Zeko) stage | F25: 1. Open the candidate's journey drawer 2. Record outcome = Approved | G25: Candidate auto-advances to the next active stage in the pipeline, 'IQ / Tech Assessment'; a stage-entered event is logged for the new stage; an outcome event is logged for HR Screening (Zeko); candidate's status label updates to 'HR Screening (Zeko) Approved'; approval outcome email sent | H25: Positive | I25: P1 | J25: Recruiter | K25: Automated - UI (fixture) | L25: MS Graph mail (delivery check only) | M25: ATS_TestCases_HRUpload_to_ZekoHR_Updated 2.xlsx | N25: It Ran fine | O25: Not Run | Q25: Locally the 'Emails in this round' log reads 'failed' (no Graph). Inbox delivery is a manual check on staging.
A26: OUT-02 | B26: Candidate Pipeline | C26: Zeko HR Screening - Outcome (Approve/Reject/Hold) | D26: Reject candidate at HR Screening (Zeko) stage | F26: 1. Record outcome = Rejected, with a valid reason | G26: Candidate stays at HR Screening (Zeko) stage (no advance); stage status = 'rejected'; status label = 'HR Screening (Zeko) Rejected'; legacy shortlist status set to 'rejected'; rejection outcome email sent | H26: Positive | I26: P1 | J26: Recruiter | K26: Automated - UI (fixture) | L26: MS Graph mail (delivery check only) | M26: ATS_TestCases_HRUpload_to_ZekoHR_Updated 2.xlsx | N26: It Ran fine | O26: Not Run
A27: OUT-03 | B27: Candidate Pipeline | C27: Zeko HR Screening - Outcome (Approve/Reject/Hold) | D27: Reject without a reason | F27: 1. Attempt to record outcome = Rejected with no reason_id and no free-text reason | G27: Request blocked: 'A reason is required for Reject/Hold outcomes' | H27: Negative | I27: P1 | J27: Recruiter | K27: Automated - UI (fixture) | L27: MS Graph mail (delivery check only) | M27: ATS_TestCases_HRUpload_to_ZekoHR_Updated 2.xlsx | N27: It Ran fine | O27: Not Run
A28: OUT-04 | B28: Candidate Pipeline | C28: Zeko HR Screening - Outcome (Approve/Reject/Hold) | D28: Reject with 'Other reasons' but no free text | F28: 1. Select the 'Other reasons' option as the reject reason 2. Submit without typing free-text | G28: Request blocked: 'Free-text reason is required when "Other reasons" is selected' | H28: Negative | I28: P1 | J28: Recruiter | K28: Automated - UI (fixture) | L28: MS Graph mail (delivery check only) | M28: ATS_TestCases_HRUpload_to_ZekoHR_Updated 2.xlsx | N28: It Ran fine | O28: Not Run
A29: OUT-05 | B29: Candidate Pipeline | C29: Zeko HR Screening - Outcome (Approve/Reject/Hold) | D29: Hold candidate at HR Screening (Zeko) stage | F29: 1. Record outcome = Hold, with a valid reason | G29: Candidate stays at HR Screening (Zeko) stage; stage status = 'hold'; status label = 'HR Screening (Zeko) On Hold'; legacy shortlist status set to 'on_hold'; no advance, no rejection, on-hold outcome email sent with valid reason | H29: Positive | I29: P1 | J29: Recruiter | K29: Automated - UI (fixture) | L29: MS Graph mail (delivery check only) | M29: ATS_TestCases_HRUpload_to_ZekoHR_Updated 2.xlsx | N29: It Ran fine | O29: Not Run
A30: OUT-06 | B30: Candidate Pipeline | C30: Zeko HR Screening - Outcome (Approve/Reject/Hold) | D30: Preview outcome email before sending | F30: 1. Open outcome preview for outcome = Approved (before actually submitting it) | G30: Returns the compiled subject/body for review; no email is actually sent; no change to candidate's stage/status | H30: Positive | I30: P1 | J30: Recruiter | K30: Automated - UI (fixture) | M30: ATS_TestCases_HRUpload_to_ZekoHR_Updated 2.xlsx | N30: It Ran fine | O30: Not Run
A31: POST-01 | B31: Candidate Pipeline | C31: Post Zeko HR Approval | D31: Candidate appears on 'IQ / Tech Assessment' column after HR Screening approval | F31: 1. Open Pipeline Tracker board | G31: Candidate's card now sits under the 'IQ / Tech Assessment' column, which is a plain manual stage (no Zeko/API integration) - Approve/Reject/Hold work the same as any standard round | H31: Positive | I31: P2 | J31: Recruiter | K31: Automated - UI (fixture) | M31: ATS_TestCases_HRUpload_to_ZekoHR_Updated 2.xlsx | N31: It Ran fine | O31: Not Run
A32: POST-02 | B32: Candidate Pipeline | C32: Post Zeko HR Approval | D32: Journey history retains full HR Screening (Zeko) trail | F32: 1. Open the candidate's journey drawer 2. Review stage history | G32: Drawer shows the full chronological event trail: entered HR Screening (Zeko) -> outcome Approved -> entered IQ / Tech Assessment, each timestamped with the acting user | H32: Positive | I32: P2 | J32: Recruiter | K32: Automated - UI (fixture) | M32: ATS_TestCases_HRUpload_to_ZekoHR_Updated 2.xlsx | N32: It Ran fine | O32: Not Run
A33: ASM-01 | B33: Candidate Pipeline | C33: IQ / Tech Assessment | D33: Candidate enters stage | F33: Approve at HR Screening (Zeko) | G33: Candidate card moves to "IQ / Tech Assessment" column | H33: Positive | I33: P1 | J33: Recruiter | K33: Automated - UI (fixture) | L33: MS Graph mail (delivery check only) | M33: ATS_TestCases_HRUpload_to_ZekoHR_Updated 2.xlsx | N33: It Ran fine | O33: Not Run
A34: ASM-02 | B34: Candidate Pipeline | C34: IQ / Tech Assessment | D34: Send Evalground Invite | F34: 1. Open the candidate's journey drawer 2. Send Evalground Invite | G34: Shows a popup as email body content where user have to add the evalground link and then Send Invite | H34: Positive | I34: P1 | J34: Recruiter | K34: Automated - UI (fixture) | L34: MS Graph mail (delivery check only) | M34: ATS_TestCases_HRUpload_to_ZekoHR_Updated 2.xlsx | N34: It Ran fine | O34: Not Run | Q34: Modal + link entry automated; inbox delivery manual.
A35: ASM-03 | B35: Candidate Pipeline | C35: IQ / Tech Assessment | D35: Re- Invite Send Evalground Invite | F35: 1. Open the candidate's journey drawer 2. Re-Invite | G35: Again Shows a popup as email body content where user have to add the evalground link and then Send Invite | H35: Positive | I35: P1 | J35: Recruiter | K35: Automated - UI (fixture) | L35: MS Graph mail (delivery check only) | M35: ATS_TestCases_HRUpload_to_ZekoHR_Updated 2.xlsx | N35: It Ran fine | O35: Not Run
A36: ASM-04 | B36: Candidate Pipeline | C36: IQ / Tech Assessment | D36: Assessment scores imported from Evalground CSV | F36: 1. At IQ / Tech Assessment, click Upload / Import 2. Choose a valid Evalground CSV containing the candidate's email 3. Confirm the import | G36: Rows matched to candidates by email; scores written to the candidate's assessment record; unmatched rows listed; optional auto approve/reject on pass mark if enabled in Settings | H36: Positive | I36: P1 | J36: Recruiter | K36: Automated - UI (fixture) | M36: ATS_TestCases_HRUpload_to_ZekoHR_Updated 2.xlsx | N36: It Ran fine | O36: Not Run | Q36: Steps/expected expanded from 'Upload csv manually'. Test data: docs/*TestReport*.csv.
A37: ASM-05 | B37: Candidate Pipeline | C37: IQ / Tech Assessment | D37: Approve | F37: Record outcome -> Approve | G37: Candidate advances to "Functional Screening (Zeko)"; status label = "IQ / Tech Assessment Approved"; email sent | H37: Positive | I37: P1 | J37: Recruiter | K37: Automated - UI (fixture) | L37: MS Graph mail (delivery check only) | M37: ATS_TestCases_HRUpload_to_ZekoHR_Updated 2.xlsx | N37: It Ran fine | O37: Not Run
A38: ASM-06 | B38: Candidate Pipeline | C38: IQ / Tech Assessment | D38: Reject without a valid reason | F38: Reject -> submit with no reason / "Other" selected with no free text | G38: Blocked: reason is mandatory | H38: Negative | I38: P1 | J38: Recruiter | K38: Automated - UI (fixture) | L38: MS Graph mail (delivery check only) | M38: ATS_TestCases_HRUpload_to_ZekoHR_Updated 2.xlsx | N38: It Ran fine | O38: Not Run
A39: ASM-07 | B39: Candidate Pipeline | C39: IQ / Tech Assessment | D39: Reject with a valid reason | F39: Reject -> pick reason -> submit | G39: Stays at same stage; status = rejected; label = "IQ / Tech Assessment Rejected"; email sent; no advance | H39: Positive | I39: P1 | J39: Recruiter | K39: Automated - UI (fixture) | L39: MS Graph mail (delivery check only) | M39: ATS_TestCases_HRUpload_to_ZekoHR_Updated 2.xlsx | N39: It Ran fine | O39: Not Run
A40: ASM-08 | B40: Candidate Pipeline | C40: IQ / Tech Assessment | D40: Hold with a valid reason | F40: Hold -> pick reason -> submit | G40: Stays at same stage; status = hold; label = "IQ / Tech Assessment On Hold" | H40: Positive | I40: P1 | J40: Recruiter | K40: Automated - UI (fixture) | L40: MS Graph mail (delivery check only) | M40: ATS_TestCases_HRUpload_to_ZekoHR_Updated 2.xlsx | N40: It Ran fine | O40: Not Run
...

Sheet Summary
A1: Module | B1: Total | C1: P1 | D1: Automated - UI | E1: Automated - UI (fixture) | F1: Automated - API | G1: Manual - External | H1: Manual - Scheduled job | I1: Manual - Exploratory | J1: Automatable | K1: Automatable % | L1: Pass | M1: Fail | N1: Not Run
A2: HR Manual Upload | B2: =COUNTIF('Test Cases'!$B$2:$B$284,$A2) | C2: =COUNTIFS('Test Cases'!$B$2:$B$284,$A2,'Test Cases'!$I$2:$I$284,"P1") | D2: =COUNTIFS('Test Cases'!$B$2:$B$284,$A2,'Test Cases'!$K$2:$K$284,"Automated - UI") | E2: =COUNTIFS('Test Cases'!$B$2:$B$284,$A2,'Test Cases'!$K$2:$K$284,"Automated - UI (fixture)") | F2: =COUNTIFS('Test Cases'!$B$2:$B$284,$A2,'Test Cases'!$K$2:$K$284,"Automated - API") | G2: =COUNTIFS('Test Cases'!$B$2:$B$284,$A2,'Test Cases'!$K$2:$K$284,"Manual - External") | H2: =COUNTIFS('Test Cases'!$B$2:$B$284,$A2,'Test Cases'!$K$2:$K$284,"Manual - Scheduled job") | I2: =COUNTIFS('Test Cases'!$B$2:$B$284,$A2,'Test Cases'!$K$2:$K$284,"Manual - Exploratory") | J2: =D2+E2+F2 | K2: =IF(B2=0,0,J2/B2) | L2: =COUNTIFS('Test Cases'!$B$2:$B$284,$A2,'Test Cases'!$O$2:$O$284,"Pass") | M2: =COUNTIFS('Test Cases'!$B$2:$B$284,$A2,'Test Cases'!$O$2:$O$284,"Fail") | N2: =COUNTIFS('Test Cases'!$B$2:$B$284,$A2,'Test Cases'!$O$2:$O$284,"Not Run")
A3: Candidate Screening | B3: =COUNTIF('Test Cases'!$B$2:$B$284,$A3) | C3: =COUNTIFS('Test Cases'!$B$2:$B$284,$A3,'Test Cases'!$I$2:$I$284,"P1") | D3: =COUNTIFS('Test Cases'!$B$2:$B$284,$A3,'Test Cases'!$K$2:$K$284,"Automated - UI") | E3: =COUNTIFS('Test Cases'!$B$2:$B$284,$A3,'Test Cases'!$K$2:$K$284,"Automated - UI (fixture)") | F3: =COUNTIFS('Test Cases'!$B$2:$B$284,$A3,'Test Cases'!$K$2:$K$284,"Automated - API") | G3: =COUNTIFS('Test Cases'!$B$2:$B$284,$A3,'Test Cases'!$K$2:$K$284,"Manual - External") | H3: =COUNTIFS('Test Cases'!$B$2:$B$284,$A3,'Test Cases'!$K$2:$K$284,"Manual - Scheduled job") | I3: =COUNTIFS('Test Cases'!$B$2:$B$284,$A3,'Test Cases'!$K$2:$K$284,"Manual - Exploratory") | J3: =D3+E3+F3 | K3: =IF(B3=0,0,J3/B3) | L3: =COUNTIFS('Test Cases'!$B$2:$B$284,$A3,'Test Cases'!$O$2:$O$284,"Pass") | M3: =COUNTIFS('Test Cases'!$B$2:$B$284,$A3,'Test Cases'!$O$2:$O$284,"Fail") | N3: =COUNTIFS('Test Cases'!$B$2:$B$284,$A3,'Test Cases'!$O$2:$O$284,"Not Run")
A4: Candidate Pipeline | B4: =COUNTIF('Test Cases'!$B$2:$B$284,$A4) | C4: =COUNTIFS('Test Cases'!$B$2:$B$284,$A4,'Test Cases'!$I$2:$I$284,"P1") | D4: =COUNTIFS('Test Cases'!$B$2:$B$284,$A4,'Test Cases'!$K$2:$K$284,"Automated - UI") | E4: =COUNTIFS('Test Cases'!$B$2:$B$284,$A4,'Test Cases'!$K$2:$K$284,"Automated - UI (fixture)") | F4: =COUNTIFS('Test Cases'!$B$2:$B$284,$A4,'Test Cases'!$K$2:$K$284,"Automated - API") | G4: =COUNTIFS('Test Cases'!$B$2:$B$284,$A4,'Test Cases'!$K$2:$K$284,"Manual - External") | H4: =COUNTIFS('Test Cases'!$B$2:$B$284,$A4,'Test Cases'!$K$2:$K$284,"Manual - Scheduled job") | I4: =COUNTIFS('Test Cases'!$B$2:$B$284,$A4,'Test Cases'!$K$2:$K$284,"Manual - Exploratory") | J4: =D4+E4+F4 | K4: =IF(B4=0,0,J4/B4) | L4: =COUNTIFS('Test Cases'!$B$2:$B$284,$A4,'Test Cases'!$O$2:$O$284,"Pass") | M4: =COUNTIFS('Test Cases'!$B$2:$B$284,$A4,'Test Cases'!$O$2:$O$284,"Fail") | N4: =COUNTIFS('Test Cases'!$B$2:$B$284,$A4,'Test Cases'!$O$2:$O$284,"Not Run")
A5: Zeko HR Screening | B5: =COUNTIF('Test Cases'!$B$2:$B$284,$A5) | C5: =COUNTIFS('Test Cases'!$B$2:$B$284,$A5,'Test Cases'!$I$2:$I$284,"P1") | D5: =COUNTIFS('Test Cases'!$B$2:$B$284,$A5,'Test Cases'!$K$2:$K$284,"Automated - UI") | E5: =COUNTIFS('Test Cases'!$B$2:$B$284,$A5,'Test Cases'!$K$2:$K$284,"Automated - UI (fixture)") | F5: =COUNTIFS('Test Cases'!$B$2:$B$284,$A5,'Test Cases'!$K$2:$K$284,"Automated - API") | G5: =COUNTIFS('Test Cases'!$B$2:$B$284,$A5,'Test Cases'!$K$2:$K$284,"Manual - External") | H5: =COUNTIFS('Test Cases'!$B$2:$B$284,$A5,'Test Cases'!$K$2:$K$284,"Manual - Scheduled job") | I5: =COUNTIFS('Test Cases'!$B$2:$B$284,$A5,'Test Cases'!$K$2:$K$284,"Manual - Exploratory") | J5: =D5+E5+F5 | K5: =IF(B5=0,0,J5/B5) | L5: =COUNTIFS('Test Cases'!$B$2:$B$284,$A5,'Test Cases'!$O$2:$O$284,"Pass") | M5: =COUNTIFS('Test Cases'!$B$2:$B$284,$A5,'Test Cases'!$O$2:$O$284,"Fail") | N5: =COUNTIFS('Test Cases'!$B$2:$B$284,$A5,'Test Cases'!$O$2:$O$284,"Not Run")
A6: Documents | B6: =COUNTIF('Test Cases'!$B$2:$B$284,$A6) | C6: =COUNTIFS('Test Cases'!$B$2:$B$284,$A6,'Test Cases'!$I$2:$I$284,"P1") | D6: =COUNTIFS('Test Cases'!$B$2:$B$284,$A6,'Test Cases'!$K$2:$K$284,"Automated - UI") | E6: =COUNTIFS('Test Cases'!$B$2:$B$284,$A6,'Test Cases'!$K$2:$K$284,"Automated - UI (fixture)") | F6: =COUNTIFS('Test Cases'!$B$2:$B$284,$A6,'Test Cases'!$K$2:$K$284,"Automated - API") | G6: =COUNTIFS('Test Cases'!$B$2:$B$284,$A6,'Test Cases'!$K$2:$K$284,"Manual - External") | H6: =COUNTIFS('Test Cases'!$B$2:$B$284,$A6,'Test Cases'!$K$2:$K$284,"Manual - Scheduled job") | I6: =COUNTIFS('Test Cases'!$B$2:$B$284,$A6,'Test Cases'!$K$2:$K$284,"Manual - Exploratory") | J6: =D6+E6+F6 | K6: =IF(B6=0,0,J6/B6) | L6: =COUNTIFS('Test Cases'!$B$2:$B$284,$A6,'Test Cases'!$O$2:$O$284,"Pass") | M6: =COUNTIFS('Test Cases'!$B$2:$B$284,$A6,'Test Cases'!$O$2:$O$284,"Fail") | N6: =COUNTIFS('Test Cases'!$B$2:$B$284,$A6,'Test Cases'!$O$2:$O$284,"Not Run")
A7: Offer & Closure | B7: =COUNTIF('Test Cases'!$B$2:$B$284,$A7) | C7: =COUNTIFS('Test Cases'!$B$2:$B$284,$A7,'Test Cases'!$I$2:$I$284,"P1") | D7: =COUNTIFS('Test Cases'!$B$2:$B$284,$A7,'Test Cases'!$K$2:$K$284,"Automated - UI") | E7: =COUNTIFS('Test Cases'!$B$2:$B$284,$A7,'Test Cases'!$K$2:$K$284,"Automated - UI (fixture)") | F7: =COUNTIFS('Test Cases'!$B$2:$B$284,$A7,'Test Cases'!$K$2:$K$284,"Automated - API") | G7: =COUNTIFS('Test Cases'!$B$2:$B$284,$A7,'Test Cases'!$K$2:$K$284,"Manual - External") | H7: =COUNTIFS('Test Cases'!$B$2:$B$284,$A7,'Test Cases'!$K$2:$K$284,"Manual - Scheduled job") | I7: =COUNTIFS('Test Cases'!$B$2:$B$284,$A7,'Test Cases'!$K$2:$K$284,"Manual - Exploratory") | J7: =D7+E7+F7 | K7: =IF(B7=0,0,J7/B7) | L7: =COUNTIFS('Test Cases'!$B$2:$B$284,$A7,'Test Cases'!$O$2:$O$284,"Pass") | M7: =COUNTIFS('Test Cases'!$B$2:$B$284,$A7,'Test Cases'!$O$2:$O$284,"Fail") | N7: =COUNTIFS('Test Cases'!$B$2:$B$284,$A7,'Test Cases'!$O$2:$O$284,"Not Run")
A8: Authentication & Access | B8: =COUNTIF('Test Cases'!$B$2:$B$284,$A8) | C8: =COUNTIFS('Test Cases'!$B$2:$B$284,$A8,'Test Cases'!$I$2:$I$284,"P1") | D8: =COUNTIFS('Test Cases'!$B$2:$B$284,$A8,'Test Cases'!$K$2:$K$284,"Automated - UI") | E8: =COUNTIFS('Test Cases'!$B$2:$B$284,$A8,'Test Cases'!$K$2:$K$284,"Automated - UI (fixture)") | F8: =COUNTIFS('Test Cases'!$B$2:$B$284,$A8,'Test Cases'!$K$2:$K$284,"Automated - API") | G8: =COUNTIFS('Test Cases'!$B$2:$B$284,$A8,'Test Cases'!$K$2:$K$284,"Manual - External") | H8: =COUNTIFS('Test Cases'!$B$2:$B$284,$A8,'Test Cases'!$K$2:$K$284,"Manual - Scheduled job") | I8: =COUNTIFS('Test Cases'!$B$2:$B$284,$A8,'Test Cases'!$K$2:$K$284,"Manual - Exploratory") | J8: =D8+E8+F8 | K8: =IF(B8=0,0,J8/B8) | L8: =COUNTIFS('Test Cases'!$B$2:$B$284,$A8,'Test Cases'!$O$2:$O$284,"Pass") | M8: =COUNTIFS('Test Cases'!$B$2:$B$284,$A8,'Test Cases'!$O$2:$O$284,"Fail") | N8: =COUNTIFS('Test Cases'!$B$2:$B$284,$A8,'Test Cases'!$O$2:$O$284,"Not Run")
A9: Admin Portal | B9: =COUNTIF('Test Cases'!$B$2:$B$284,$A9) | C9: =COUNTIFS('Test Cases'!$B$2:$B$284,$A9,'Test Cases'!$I$2:$I$284,"P1") | D9: =COUNTIFS('Test Cases'!$B$2:$B$284,$A9,'Test Cases'!$K$2:$K$284,"Automated - UI") | E9: =COUNTIFS('Test Cases'!$B$2:$B$284,$A9,'Test Cases'!$K$2:$K$284,"Automated - UI (fixture)") | F9: =COUNTIFS('Test Cases'!$B$2:$B$284,$A9,'Test Cases'!$K$2:$K$284,"Automated - API") | G9: =COUNTIFS('Test Cases'!$B$2:$B$284,$A9,'Test Cases'!$K$2:$K$284,"Manual - External") | H9: =COUNTIFS('Test Cases'!$B$2:$B$284,$A9,'Test Cases'!$K$2:$K$284,"Manual - Scheduled job") | I9: =COUNTIFS('Test Cases'!$B$2:$B$284,$A9,'Test Cases'!$K$2:$K$284,"Manual - Exploratory") | J9: =D9+E9+F9 | K9: =IF(B9=0,0,J9/B9) | L9: =COUNTIFS('Test Cases'!$B$2:$B$284,$A9,'Test Cases'!$O$2:$O$284,"Pass") | M9: =COUNTIFS('Test Cases'!$B$2:$B$284,$A9,'Test Cases'!$O$2:$O$284,"Fail") | N9: =COUNTIFS('Test Cases'!$B$2:$B$284,$A9,'Test Cases'!$O$2:$O$284,"Not Run")
A10: Dashboard & Notifications | B10: =COUNTIF('Test Cases'!$B$2:$B$284,$A10) | C10: =COUNTIFS('Test Cases'!$B$2:$B$284,$A10,'Test Cases'!$I$2:$I$284,"P1") | D10: =COUNTIFS('Test Cases'!$B$2:$B$284,$A10,'Test Cases'!$K$2:$K$284,"Automated - UI") | E10: =COUNTIFS('Test Cases'!$B$2:$B$284,$A10,'Test Cases'!$K$2:$K$284,"Automated - UI (fixture)") | F10: =COUNTIFS('Test Cases'!$B$2:$B$284,$A10,'Test Cases'!$K$2:$K$284,"Automated - API") | G10: =COUNTIFS('Test Cases'!$B$2:$B$284,$A10,'Test Cases'!$K$2:$K$284,"Manual - External") | H10: =COUNTIFS('Test Cases'!$B$2:$B$284,$A10,'Test Cases'!$K$2:$K$284,"Manual - Scheduled job") | I10: =COUNTIFS('Test Cases'!$B$2:$B$284,$A10,'Test Cases'!$K$2:$K$284,"Manual - Exploratory") | J10: =D10+E10+F10 | K10: =IF(B10=0,0,J10/B10) | L10: =COUNTIFS('Test Cases'!$B$2:$B$284,$A10,'Test Cases'!$O$2:$O$284,"Pass") | M10: =COUNTIFS('Test Cases'!$B$2:$B$284,$A10,'Test Cases'!$O$2:$O$284,"Fail") | N10: =COUNTIFS('Test Cases'!$B$2:$B$284,$A10,'Test Cases'!$O$2:$O$284,"Not Run")
A11: MRF | B11: =COUNTIF('Test Cases'!$B$2:$B$284,$A11) | C11: =COUNTIFS('Test Cases'!$B$2:$B$284,$A11,'Test Cases'!$I$2:$I$284,"P1") | D11: =COUNTIFS('Test Cases'!$B$2:$B$284,$A11,'Test Cases'!$K$2:$K$284,"Automated - UI") | E11: =COUNTIFS('Test Cases'!$B$2:$B$284,$A11,'Test Cases'!$K$2:$K$284,"Automated - UI (fixture)") | F11: =COUNTIFS('Test Cases'!$B$2:$B$284,$A11,'Test Cases'!$K$2:$K$284,"Automated - API") | G11: =COUNTIFS('Test Cases'!$B$2:$B$284,$A11,'Test Cases'!$K$2:$K$284,"Manual - External") | H11: =COUNTIFS('Test Cases'!$B$2:$B$284,$A11,'Test Cases'!$K$2:$K$284,"Manual - Scheduled job") | I11: =COUNTIFS('Test Cases'!$B$2:$B$284,$A11,'Test Cases'!$K$2:$K$284,"Manual - Exploratory") | J11: =D11+E11+F11 | K11: =IF(B11=0,0,J11/B11) | L11: =COUNTIFS('Test Cases'!$B$2:$B$284,$A11,'Test Cases'!$O$2:$O$284,"Pass") | M11: =COUNTIFS('Test Cases'!$B$2:$B$284,$A11,'Test Cases'!$O$2:$O$284,"Fail") | N11: =COUNTIFS('Test Cases'!$B$2:$B$284,$A11,'Test Cases'!$O$2:$O$284,"Not Run")
A12: Vendor | B12: =COUNTIF('Test Cases'!$B$2:$B$284,$A12) | C12: =COUNTIFS('Test Cases'!$B$2:$B$284,$A12,'Test Cases'!$I$2:$I$284,"P1") | D12: =COUNTIFS('Test Cases'!$B$2:$B$284,$A12,'Test Cases'!$K$2:$K$284,"Automated - UI") | E12: =COUNTIFS('Test Cases'!$B$2:$B$284,$A12,'Test Cases'!$K$2:$K$284,"Automated - UI (fixture)") | F12: =COUNTIFS('Test Cases'!$B$2:$B$284,$A12,'Test Cases'!$K$2:$K$284,"Automated - API") | G12: =COUNTIFS('Test Cases'!$B$2:$B$284,$A12,'Test Cases'!$K$2:$K$284,"Manual - External") | H12: =COUNTIFS('Test Cases'!$B$2:$B$284,$A12,'Test Cases'!$K$2:$K$284,"Manual - Scheduled job") | I12: =COUNTIFS('Test Cases'!$B$2:$B$284,$A12,'Test Cases'!$K$2:$K$284,"Manual - Exploratory") | J12: =D12+E12+F12 | K12: =IF(B12=0,0,J12/B12) | L12: =COUNTIFS('Test Cases'!$B$2:$B$284,$A12,'Test Cases'!$O$2:$O$284,"Pass") | M12: =COUNTIFS('Test Cases'!$B$2:$B$284,$A12,'Test Cases'!$O$2:$O$284,"Fail") | N12: =COUNTIFS('Test Cases'!$B$2:$B$284,$A12,'Test Cases'!$O$2:$O$284,"Not Run")
A13: Recruitment Analytics | B13: =COUNTIF('Test Cases'!$B$2:$B$284,$A13) | C13: =COUNTIFS('Test Cases'!$B$2:$B$284,$A13,'Test Cases'!$I$2:$I$284,"P1") | D13: =COUNTIFS('Test Cases'!$B$2:$B$284,$A13,'Test Cases'!$K$2:$K$284,"Automated - UI") | E13: =COUNTIFS('Test Cases'!$B$2:$B$284,$A13,'Test Cases'!$K$2:$K$284,"Automated - UI (fixture)") | F13: =COUNTIFS('Test Cases'!$B$2:$B$284,$A13,'Test Cases'!$K$2:$K$284,"Automated - API") | G13: =COUNTIFS('Test Cases'!$B$2:$B$284,$A13,'Test Cases'!$K$2:$K$284,"Manual - External") | H13: =COUNTIFS('Test Cases'!$B$2:$B$284,$A13,'Test Cases'!$K$2:$K$284,"Manual - Scheduled job") | I13: =COUNTIFS('Test Cases'!$B$2:$B$284,$A13,'Test Cases'!$K$2:$K$284,"Manual - Exploratory") | J13: =D13+E13+F13 | K13: =IF(B13=0,0,J13/B13) | L13: =COUNTIFS('Test Cases'!$B$2:$B$284,$A13,'Test Cases'!$O$2:$O$284,"Pass") | M13: =COUNTIFS('Test Cases'!$B$2:$B$284,$A13,'Test Cases'!$O$2:$O$284,"Fail") | N13: =COUNTIFS('Test Cases'!$B$2:$B$284,$A13,'Test Cases'!$O$2:$O$284,"Not Run")
... A18: Settings & Configuration | B18: =COUNTIF('Test Cases'!$B$2:$B$284,$A18) | C18: =COUNTIFS('Test Cases'!$B$2:$B$284,$A18,'Test Cases'!$I$2:$I$284,"P1") | D18: =COUNTIFS('Test Cases'!$B$2:$B$284,$A18,'Test Cases'!$K$2:$K$284,"Automated - UI") | E18: =COUNTIFS('Test Cases'!$B$2:$B$284,$A18,'Test Cases'!$K$2:$K$284,"Automated - UI (fixture)") | F18: =COUNTIFS('Test Cases'!$B$2:$B$284,$A18,'Test Cases'!$K$2:$K$284,"Automated - API") | G18: =COUNTIFS('Test Cases'!$B$2:$B$284,$A18,'Test Cases'!$K$2:$K$284,"Manual - External") | H18: =COUNTIFS('Test Cases'!$B$2:$B$284,$A18,'Test Cases'!$K$2:$K$284,"Manual - Scheduled job") | I18: =COUNTIFS('Test Cases'!$B$2:$B$284,$A18,'Test Cases'!$K$2:$K$284,"Manual - Exploratory") | J18: =D18+E18+F18 | K18: =IF(B18=0,0,J18/B18) | L18: =COUNTIFS('Test Cases'!$B$2:$B$284,$A18,'Test Cases'!$O$2:$O$284,"Pass") | M18: =COUNTIFS('Test Cases'!$B$2:$B$284,$A18,'Test Cases'!$O$2:$O$284,"Fail") | N18: =COUNTIFS('Test Cases'!$B$2:$B$284,$A18,'Test Cases'!$O$2:$O$284,"Not Run")
A19: Total | B19: =SUM(B2:B18) | C19: =SUM(C2:C18) | D19: =SUM(D2:D18) | E19: =SUM(E2:E18) | F19: =SUM(F2:F18) | G19: =SUM(G2:G18) | H19: =SUM(H2:H18) | I19: =SUM(I2:I18) | J19: =SUM(J2:J18) | K19: =IF(B19=0,0,J19/B19) | L19: =SUM(L2:L18) | M19: =SUM(M2:M18) | N19: =SUM(N2:N18)

Sheet Changes vs Previous
A1: TC ID | B1: What changed | C1: Why
A2: HRU-01 | B2: Remark added | C2: Total Experience defect fixed in CHANGES-2026-08-07 #19. Re-test with a CV using 'Jun-2022 - Present', then Search Candidate > View Details.
A3: HRU-02 | B3: Remark added | C3: Scenario title says 'exceeding max count/size' but steps/expected describe a multi-file success. Re-word before next run. Total Experience fix: #19.
A4: HRU-06 | B4: Remark added | C4: Never executed (no Actual Result in the 2026-08-11 pass).
A5: HRU-07 | B5: Remark added | C5: Never executed. Missing-data link also exercised by MJD-01..04.
A6: HRU-08 | B6: Remark added | C6: Never executed.
A7: HRU-09 | B7: Updated: automation | C7: Never executed. Live socket update itself is automatable once a job can be produced without the AI parser.
A8: SCR-05 | B8: Remark added | C8: Validation itself is client-side; only reaching the result list needs AI search.
A9: CPIPE-01 | B9: Updated: pre
A10: CPIPE-02 | B10: Updated: pre
A11: ZHR-04 | B11: Updated: expected | C11: Expected result clarified (was 'As it's Optional').
A12: ZHR-05 | B12: Updated: automation
A13: ZHR-06 | B13: Updated: automation | C13: Never executed.
A14: OUT-01 | B14: Remark added | C14: Locally the 'Emails in this round' log reads 'failed' (no Graph). Inbox delivery is a manual check on staging.
A15: ASM-02 | B15: Updated: automation | C15: Modal + link entry automated; inbox delivery manual.
A16: ASM-03 | B16: Updated: automation
A17: ASM-04 | B17: Updated: scenario, steps, expected, automation | C17: Steps/expected expanded from 'Upload csv manually'. Test data: docs/*TestReport*.csv.
A18: ZFN-02 | B18: Updated: scenario, steps, expected, automation | C18: Original row had no steps/expected.
A19: T1-03 | B19: Updated: type
A20: T1-07 | B20: Remark added | C20: Preview text must already show 'Hi <interviewer name>,' (fix #20).
A21: T1-08 | B21: Updated: automation
A22: T1-09 | B22: Updated: automation | C22: Interviewer-name defect fixed in CHANGES-2026-08-07 #20; needs re-run of prisma/seed-email-templates.js.
A23: T1-10 | B23: Updated: pre
A24: T1-11 | B24: Updated: steps
A25: T1-12 | B25: Updated: expected, type | C25: Open 'Verify' item resolved from code.
A26: T1-13 | B26: Updated: expected, type | C26: Open 'Verify' item resolved from code.
A27: T1-15 | B27: Updated: automation | C27: Open product question - confirm with RT whether outcome before interview is intended.
A28: T2-02 | B28: Remark added | C28: Covered by repeating T1-02..T1-15 on Technical Round 2.
A29: T3-02 | B29: Remark added | C29: Covered by repeating T1-02..T1-15 on Technical Round 3.
A30: T3-03 | B30: Updated: expected | C30: Expected result was a copy of the steps; corrected.
A31: T3-08 | B31: Updated: steps, expected | C31: Skip control now exists in the drawer UI.
A32: CLI-07 | B32: Updated: steps, expected | C32: Skip control now exists in the drawer UI.
A33: DOC-02 | B33: Updated: steps, expected | C33: Inbox delivery is manual; request creation automated.
A34: OFR-01 | B34: Updated: expected | C34: Offer stage became record-only on 2026-08-25 (CHANGES-2026-08-25-client-round-and-offer-mark-only.md). Approve/Reject/Hold no longer exist on Offer.
A35: OFR-02 | B35: Updated: scenario, steps, expected | C35: Offer stage became record-only on 2026-08-25 (CHANGES-2026-08-25-client-round-and-offer-mark-only.md). Approve/Reject/Hold no longer exist on Offer.
A36: OFR-03 | B36: Updated: scenario, steps, expected, type | C36: Offer stage became record-only on 2026-08-25 (CHANGES-2026-08-25-client-round-and-offer-mark-only.md). Approve/Reject/Hold no longer exist on Offer.
... A45: New modules | B45: Admin Portal, Authentication & Access, Candidate Missing Data, Candidate Pipeline, Dashboard & Notifications, Documents, Email Templates, HR Manual Upload, Interviewer Scorecard, MRF, Offer & Closure, Recruitment Analytics, Search Candidate, Settings & Configuration, Vendor | C45: Not covered by the previous sheet
